Workbook

Sheet Читай меня
A1: ЕГЭ·ПРО — материалы для Яндекс Директа
A2: Подготовлено 19.09.2026 по инструкции «Продвижение ЕГЭ·ПРО в Яндексе». Кабинет не открывался, ничего не запускалось.
A4: Сводка проверок (считается формулами)
A5: Кампаний | B5: =COUNTA(Кампании!A5:A11)
A6: Ключевых фраз | B6: =COUNTA('Группы и фразы'!C5:C1000)
A7: Фраз с ошибкой (больше 7 слов) | B7: =COUNTIF('Группы и фразы'!G5:G1000,"ошибка")
A8: Объявлений | B8: =COUNTA(Объявления!D5:D300)
A9: Объявлений, которые нужно проверить по лимитам | B9: =COUNTIF(Объявления!O5:O300,"проверить")
A10: Доли бюджета волны 1 = 100% | B10: =IF(ABS(Кампании!G13-1)<0.0001,"OK","не 100%")
A11: Доли бюджета волны 2 = 100% | B11: =IF(ABS(Кампании!G14-1)<0.0001,"OK","не 100%")
A12: Кампании ниже минимального дневного бюджета | B12: =COUNTIF(Кампании!J5:J11,"ниже минимума")
A13: Минус-слова «Все кампании», знаков без пробелов (лимит 20 000) | B13: ='Минус-слова'!F5
A15: Что в книге
A16: Настройки | B16: Ваши вводные: бюджет, регион, цены. Жёлтые ячейки с синим шрифтом — заменить своими.
A17: Кампании | B17: 7 кампаний в двух волнах, бюджеты считаются от «Настроек».
A18: Группы и фразы | B18: Ключевые фразы по группам, с проверкой числа слов (не больше 7).
A19: Объявления | B19: Тексты для поиска: 2 варианта на группу (A/B), с проверкой лимитов Директа.
A20: Минус-слова | B20: Общие и по кампаниям (перекрёстные — чтобы свои кампании не конкурировали).
A21: Быстрые ссылки / Уточнения | B21: Расширения объявлений, с проверкой длины.
A22: Мастер кампаний | B22: Заголовки, тексты, изображения и образец фраз для Мастера.
A23: Ретаргетинг и LAL | B23: Сегменты и тексты для второй волны.
A24: Цели и метки | B24: Цели Метрики, метки в ссылках.
A25: Чек-лист | B25: Что делаю я, что вы, в каком порядке.
A27: Как я изменил подход относительно артефакта (и почему)
A28: Не «официальный банк ФИПИ» | B28: В подвале сайта сказано, что проект не является официальным ресурсом ФИПИ. В рекламе — «задания формата ФИПИ» (формулировка сайта). В артефакте было «официальный» — это надо исправить.
A29: Нет сравнений с репетиторами | B29: «Дешевле часа с репетитором» — недоказуемое сравнение, Директ и закон о рекламе такое не любят. В текстах только факты о нашей цене и оплате за месяц.
A30: «Безлимит» — на 2, 4 или 5 предметов | B30: В артефакте было «по всем предметам от 1990 ₽». По данным прода АТТЕСТАТ (1 990 ₽) — 2 предмета на выбор, ВУЗ (3 990 ₽) — 4, ВУЗ+ (4 990 ₽) — 5. Тексты уточнены.
A31: Информатика не рекламируется | B31: В описании сайта она упомянута, но заданий по информатике на проде нет. Слово вынесено в минус-слова. Описание сайта стоит поправить.
A32: Сочинение по русскому не рекламируется | B32: Проверка по критериям есть у биологии (2 605 заданий), обществознания (1 847), истории (1 105), литературы (862), географии, математики, физики, химии. У русского языка — 1 задание. Самый частый запрос ниши («проверка сочинения ЕГЭ по русскому») платформа не закрывает — это разрыв продукта, а не рекламы.
A33: Математика базового уровня не в рекламе | B33: Задания есть (1 895), но актуальность базового ЕГЭ в 2027 году я проверить не смог — прежде чем рекламировать, уточните.
A34: «Отзывы» не в фразах и текстах | B34: Отзывов на сайте нет; обещать их в рекламе нельзя.
A35: Все объявления ведут на «/» или «/tariffs» | B35: У приложения нет прямых ссылок на предметы и экраны (навигация без адресов). Предметные объявления ведут на главную. Для роста релевантности стоит сделать адреса вида /?subject=math — это задача для разработки.
A37: Чего я не знаю (честно)
A38: Частотности и цены кликов | B38: Доступа к Wordstat и «Прогнозу бюджета» у меня нет. Фразы составлены по типичным формулировкам, а не по данным. Перед запуском прогоните их через «Прогноз бюджета» и уберите пустые.
A39: Точные названия элементов интерфейса | B39: Директ меняет интерфейс. Названия категорий автотаргетинга и т. п. я указал по памяти, при заполнении кабинета сверю с экраном.
A40: Ставки | B40: Максимальные ставки не выставлены: без прогноза любое число было бы выдумкой.
A41: Допущения о деньгах | B41: Бюджеты в «Настройках» — мои допущения (верх диапазона из инструкции), замените своими.

Sheet Настройки
A1: Настройки
A2: Жёлтые ячейки с синим шрифтом — ваши вводные. Всё остальное считается от них.
A3: Параметр | B3: Значение | C3: Источник / примечание
A4: Дневной бюджет волны 1, ₽ | B4: 2000 | C4: Допущение: 14 дней × 2 000 ₽ = 28 000 ₽ — верх диапазона 15–30 тыс. ₽ из инструкции (раздел 7.2). Замените своим.
A5: Дневной бюджет волны 2, ₽ | B5: 2000 | C5: Допущение. Волна 2 включается через 1–2 недели, когда в Метрике есть данные.
A6: Минимальный дневной бюджет кампании, ₽ | B6: 300 | C6: Источник: справка Директа «Минимальный бюджет» (yandex.ru/support/direct/ru/strategies/minimal-budget). Для обучения алгоритмов нужно больше — от 1 500 ₽/день на кампанию по инструкции.
A7: Дней теста волны 1 | B7: 14 | C7: Допущение (две недели — по инструкции).
A8: Сайт | B8: https://ege-tutor.ru | C8: Прод-домен.
A9: Номер счётчика Метрики | B9: 112809756 | C9: Источник: вы (код счётчика в чате).
A10: Регион показа | B10: Россия | C10: Допущение: вся Россия. Если нужны отдельные города — заменить (ответа на вопрос о регионе не было).
A11: Тариф «АТТЕСТАТ», ₽/мес | B11: 1990 | C11: Источник: таблица public.tariffs на проде, 19.09.2026: 2 предмета, безлимитный ИИ. Цена зашита в тексты объявлений — при изменении править тексты.
A12: Тариф «ВУЗ», ₽/мес | B12: 3990 | C12: Там же: 4 предмета.
A13: Тариф «ВУЗ+», ₽/мес | B13: 4990 | C13: Там же: 5 предметов.
A14: Бесплатных обращений к ИИ в день | B14: 3 | C14: Там же (тариф «Попробовать»: 2 предмета, до 3 обращений в день).
A16: Бюджет теста волны 1 за период, ₽ | B16: =B4*B7 | C16: Дневной бюджет волны 1 × дни теста

Sheet Кампании
A1: Кампании
A2: Волна 1 — старт; волна 2 — через 1–2 недели, когда в Метрике есть данные. Доли — ваш ввод (в сумме 100% по каждой волне).
A4: ID | B4: Название | C4: Волна | D4: Тип в Директе | E4: Где показывать | F4: Стратегия на старте | G4: Доля бюджета волны | H4: Дневной бюджет, ₽ | I4: Недельный бюджет, ₽ | J4: Проверка минимума | K4: Фраз | L4: Объявлений | M4: Посадочная | N4: Цель для обучения | O4: Комментарий
A5: K1 | B5: Мастер кампаний | ИИ-репетитор ЕГЭ | C5: 1 | D5: Мастер кампаний | E5: Поиск + РСЯ + внешние площадки (подбирает Яндекс) | F5: Максимум кликов, недельный бюджет | G5: 0.4 | H5: =IF(C5=1,Настройки!$B$4,Настройки!$B$5)*G5 | I5: =H5*7 | J5: =IF(H5>=Настройки!$B$6,"OK","ниже минимума") | K5: =COUNTIF('Группы и фразы'!$A$5:$A$1000,A5) | L5: =COUNTIF(Объявления!$A$5:$A$300,A5) | M5: / | N5: signup (пока нет данных — клики) | O5: Изображения — на листе «Мастер кампаний». Ключевые фразы для Мастера — необязательны, образец там же.
A6: K2 | B6: Поиск | ИИ-репетитор и тренажёр ЕГЭ | C6: 1 | D6: Текстово-графические объявления | E6: Только поиск | F6: Максимум кликов, недельный бюджет (или ручные ставки) | G6: 0.3 | H6: =IF(C6=1,Настройки!$B$4,Настройки!$B$5)*G6 | I6: =H6*7 | J6: =IF(H6>=Настройки!$B$6,"OK","ниже минимума") | K6: =COUNTIF('Группы и фразы'!$A$5:$A$1000,A6) | L6: =COUNTIF(Объявления!$A$5:$A$300,A6) | M6: / | N6: signup (пока нет данных — клики) | O6: Автотаргетинг: оставить только «Целевые» и «Узкие» запросы, остальные категории выключить (названия в интерфейсе могут отличаться). Предметные слова — в минус-словах кампании.
A7: K3 | B7: Поиск | Предметы ЕГЭ | C7: 1 | D7: Текстово-графические объявления | E7: Только поиск | F7: Максимум кликов, недельный бюджет (или ручные ставки) | G7: 0.3 | H7: =IF(C7=1,Настройки!$B$4,Настройки!$B$5)*G7 | I7: =H7*7 | J7: =IF(H7>=Настройки!$B$6,"OK","ниже минимума") | K7: =COUNTIF('Группы и фразы'!$A$5:$A$1000,A7) | L7: =COUNTIF(Объявления!$A$5:$A$300,A7) | M7: / | N7: signup (пока нет данных — клики) | O7: 10 групп по предметам; на старте включать только группы с волной 1 (столбец E листа «Группы и фразы»).
A8: K4 | B8: Поиск | Развёрнутые ответы (часть 2) | C8: 2 | D8: Текстово-графические объявления | E8: Только поиск | F8: Максимум кликов, недельный бюджет | G8: 0.15 | H8: =IF(C8=1,Настройки!$B$4,Настройки!$B$5)*G8 | I8: =H8*7 | J8: =IF(H8>=Настройки!$B$6,"OK","ниже минимума") | K8: =COUNTIF('Группы и фразы'!$A$5:$A$1000,A8) | L8: =COUNTIF(Объявления!$A$5:$A$300,A8) | M8: /tariffs | N8: tariffs_view / checkout_start | O8: Проверка по критериям — функция платных тарифов, поэтому посадочная — страница тарифов. Русский язык не рекламируем (см. «Читай меня»).
A9: K5 | B9: Поиск | Родители | C9: 2 | D9: Текстово-графические объявления | E9: Только поиск | F9: Максимум кликов, недельный бюджет | G9: 0.35 | H9: =IF(C9=1,Настройки!$B$4,Настройки!$B$5)*G9 | I9: =H9*7 | J9: =IF(H9>=Настройки!$B$6,"OK","ниже минимума") | K9: =COUNTIF('Группы и фразы'!$A$5:$A$1000,A9) | L9: =COUNTIF(Объявления!$A$5:$A$300,A9) | M9: /tariffs (цены) и / (остальные группы) | N9: tariffs_view / checkout_start | O9: Аудитория, которая платит. Отзывов и сравнений с репетиторами в текстах нет намеренно.
A10: K6 | B10: Поиск | Информационные (низкие ставки) | C10: 2 | D10: Текстово-графические объявления | E10: Только поиск | F10: Максимум кликов, недельный бюджет, низкая ставка | G10: 0.15 | H10: =IF(C10=1,Настройки!$B$4,Настройки!$B$5)*G10 | I10: =H10*7 | J10: =IF(H10>=Настройки!$B$6,"OK","ниже минимума") | K10: =COUNTIF('Группы и фразы'!$A$5:$A$1000,A10) | L10: =COUNTIF(Объявления!$A$5:$A$300,A10) | M10: / | N10: signup | O10: Верх воронки. Запускать только после результатов K2–K3; ставки держать ниже, чем в горячих кампаниях.
A11: K7 | B11: РСЯ | Ретаргетинг | C11: 2 | D11: ТГО / ЕПК на сегментах Метрики | E11: РСЯ (по сегментам Метрики) | F11: Максимум кликов → оптимизация конверсий | G11: 0.35 | H11: =IF(C11=1,Настройки!$B$4,Настройки!$B$5)*G11 | I11: =H11*7 | J11: =IF(H11>=Настройки!$B$6,"OK","ниже минимума") | K11: =COUNTIF('Группы и фразы'!$A$5:$A$1000,A11) | L11: =COUNTIF(Объявления!$A$5:$A$300,A11) | M11: /tariffs | N11: checkout_start / purchase | O11: Создавать, когда в Метрике накопится аудитория (минимум 1–2 недели показов). Сегменты — лист «Ретаргетинг и LAL».
B13: Сумма долей волны 1 | G13: =SUMIF(C5:C11,1,G5:G11)
B14: Сумма долей волны 2 | G14: =SUMIF(C5:C11,2,G5:G11)
B15: Дневной бюджет всех кампаний, ₽ | H15: =SUM(H5:H11)

Sheet Группы и фразы
A1: Группы и ключевые фразы
A2: Фразы — без операторов. Частотности не проверены (нет доступа к Wordstat). «Волна группы» — когда включать группу внутри кампании.
A4: Кампания | B4: Группа | C4: Ключевая фраза | D4: Тип | E4: Волна группы | F4: Слов | G4: Проверка | H4: Комментарий
A5: K2 | B5: ИИ-репетитор | C5: ии репетитор егэ | D5: Горячая | E5: 1 | F5: =LEN(TRIM(C5))-LEN(SUBSTITUTE(TRIM(C5)," ",""))+1 | G5: =IF(AND(F5<=7,LEN(C5)<=4096),"OK","ошибка")
A6: K2 | B6: ИИ-репетитор | C6: ии репетитор для егэ | D6: Горячая | E6: 1 | F6: =LEN(TRIM(C6))-LEN(SUBSTITUTE(TRIM(C6)," ",""))+1 | G6: =IF(AND(F6<=7,LEN(C6)<=4096),"OK","ошибка")
A7: K2 | B7: ИИ-репетитор | C7: ии репетитор для подготовки к егэ | D7: Горячая | E7: 1 | F7: =LEN(TRIM(C7))-LEN(SUBSTITUTE(TRIM(C7)," ",""))+1 | G7: =IF(AND(F7<=7,LEN(C7)<=4096),"OK","ошибка")
A8: K2 | B8: ИИ-репетитор | C8: репетитор с ии егэ | D8: Горячая | E8: 1 | F8: =LEN(TRIM(C8))-LEN(SUBSTITUTE(TRIM(C8)," ",""))+1 | G8: =IF(AND(F8<=7,LEN(C8)<=4096),"OK","ошибка")
A9: K2 | B9: ИИ-репетитор | C9: нейросеть репетитор егэ | D9: Горячая | E9: 1 | F9: =LEN(TRIM(C9))-LEN(SUBSTITUTE(TRIM(C9)," ",""))+1 | G9: =IF(AND(F9<=7,LEN(C9)<=4096),"OK","ошибка")
A10: K2 | B10: ИИ-репетитор | C10: нейросеть для подготовки к егэ | D10: Горячая | E10: 1 | F10: =LEN(TRIM(C10))-LEN(SUBSTITUTE(TRIM(C10)," ",""))+1 | G10: =IF(AND(F10<=7,LEN(C10)<=4096),"OK","ошибка")
A11: K2 | B11: ИИ-репетитор | C11: искусственный интеллект для подготовки к егэ | D11: Горячая | E11: 1 | F11: =LEN(TRIM(C11))-LEN(SUBSTITUTE(TRIM(C11)," ",""))+1 | G11: =IF(AND(F11<=7,LEN(C11)<=4096),"OK","ошибка")
A12: K2 | B12: ИИ-репетитор | C12: ии помощник для подготовки к егэ | D12: Горячая | E12: 1 | F12: =LEN(TRIM(C12))-LEN(SUBSTITUTE(TRIM(C12)," ",""))+1 | G12: =IF(AND(F12<=7,LEN(C12)<=4096),"OK","ошибка")
A13: K2 | B13: ИИ-репетитор | C13: ии тренер по егэ | D13: Горячая | E13: 1 | F13: =LEN(TRIM(C13))-LEN(SUBSTITUTE(TRIM(C13)," ",""))+1 | G13: =IF(AND(F13<=7,LEN(C13)<=4096),"OK","ошибка")
A14: K2 | B14: ИИ-репетитор | C14: онлайн репетитор ии | D14: Горячая | E14: 1 | F14: =LEN(TRIM(C14))-LEN(SUBSTITUTE(TRIM(C14)," ",""))+1 | G14: =IF(AND(F14<=7,LEN(C14)<=4096),"OK","ошибка")
A15: K2 | B15: ИИ-репетитор | C15: ai репетитор егэ | D15: Горячая | E15: 1 | F15: =LEN(TRIM(C15))-LEN(SUBSTITUTE(TRIM(C15)," ",""))+1 | G15: =IF(AND(F15<=7,LEN(C15)<=4096),"OK","ошибка")
A16: K2 | B16: ИИ-репетитор | C16: репетитор на основе ии | D16: Горячая | E16: 1 | F16: =LEN(TRIM(C16))-LEN(SUBSTITUTE(TRIM(C16)," ",""))+1 | G16: =IF(AND(F16<=7,LEN(C16)<=4096),"OK","ошибка")
... A37: K2 | B37: Платформа подготовки | C37: подготовка к егэ дома онлайн | D37: Горячая | E37: 1 | F37: =LEN(TRIM(C37))-LEN(SUBSTITUTE(TRIM(C37)," ",""))+1 | G37: =IF(AND(F37<=7,LEN(C37)<=4096),"OK","ошибка")
A38: K2 | B38: ЕГЭ 2027 | C38: подготовка к егэ 2027 | D38: Горячая | E38: 1 | F38: =LEN(TRIM(C38))-LEN(SUBSTITUTE(TRIM(C38)," ",""))+1 | G38: =IF(AND(F38<=7,LEN(C38)<=4096),"OK","ошибка") | H38: Год экзамена — 2027 (сентябрь 2026). Проверить частотность в Wordstat.
A39: K2 | B39: ЕГЭ 2027 | C39: егэ 2027 подготовка онлайн | D39: Горячая | E39: 1 | F39: =LEN(TRIM(C39))-LEN(SUBSTITUTE(TRIM(C39)," ",""))+1 | G39: =IF(AND(F39<=7,LEN(C39)<=4096),"OK","ошибка") | H39: Год экзамена — 2027 (сентябрь 2026). Проверить частотность в Wordstat.
A40: K2 | B40: ЕГЭ 2027 | C40: тренажер егэ 2027 | D40: Горячая | E40: 1 | F40: =LEN(TRIM(C40))-LEN(SUBSTITUTE(TRIM(C40)," ",""))+1 | G40: =IF(AND(F40<=7,LEN(C40)<=4096),"OK","ошибка") | H40: Год экзамена — 2027 (сентябрь 2026). Проверить частотность в Wordstat.
A41: K2 | B41: ЕГЭ 2027 | C41: задания егэ 2027 | D41: Горячая | E41: 1 | F41: =LEN(TRIM(C41))-LEN(SUBSTITUTE(TRIM(C41)," ",""))+1 | G41: =IF(AND(F41<=7,LEN(C41)<=4096),"OK","ошибка") | H41: Год экзамена — 2027 (сентябрь 2026). Проверить частотность в Wordstat.
A42: K2 | B42: ЕГЭ 2027 | C42: егэ 2027 репетитор онлайн | D42: Горячая | E42: 1 | F42: =LEN(TRIM(C42))-LEN(SUBSTITUTE(TRIM(C42)," ",""))+1 | G42: =IF(AND(F42<=7,LEN(C42)<=4096),"OK","ошибка") | H42: Год экзамена — 2027 (сентябрь 2026). Проверить частотность в Wordstat.
A43: K2 | B43: ЕГЭ 2027 | C43: егэ 2027 ии | D43: Горячая | E43: 1 | F43: =LEN(TRIM(C43))-LEN(SUBSTITUTE(TRIM(C43)," ",""))+1 | G43: =IF(AND(F43<=7,LEN(C43)<=4096),"OK","ошибка") | H43: Год экзамена — 2027 (сентябрь 2026). Проверить частотность в Wordstat.
A44: K2 | B44: ЕГЭ 2027 | C44: подготовка к егэ 2027 самостоятельно | D44: Горячая | E44: 1 | F44: =LEN(TRIM(C44))-LEN(SUBSTITUTE(TRIM(C44)," ",""))+1 | G44: =IF(AND(F44<=7,LEN(C44)<=4096),"OK","ошибка") | H44: Год экзамена — 2027 (сентябрь 2026). Проверить частотность в Wordstat.
A45: K3 | B45: ЕГЭ математика | C45: подготовка к егэ по математике профиль | D45: Тёплая | E45: 1 | F45: =LEN(TRIM(C45))-LEN(SUBSTITUTE(TRIM(C45)," ",""))+1 | G45: =IF(AND(F45<=7,LEN(C45)<=4096),"OK","ошибка")
A46: K3 | B46: ЕГЭ математика | C46: егэ математика профиль онлайн подготовка | D46: Тёплая | E46: 1 | F46: =LEN(TRIM(C46))-LEN(SUBSTITUTE(TRIM(C46)," ",""))+1 | G46: =IF(AND(F46<=7,LEN(C46)<=4096),"OK","ошибка")
A47: K3 | B47: ЕГЭ математика | C47: тренажер егэ математика профиль | D47: Тёплая | E47: 1 | F47: =LEN(TRIM(C47))-LEN(SUBSTITUTE(TRIM(C47)," ",""))+1 | G47: =IF(AND(F47<=7,LEN(C47)<=4096),"OK","ошибка")
A48: K3 | B48: ЕГЭ математика | C48: задания егэ математика профиль онлайн | D48: Тёплая | E48: 1 | F48: =LEN(TRIM(C48))-LEN(SUBSTITUTE(TRIM(C48)," ",""))+1 | G48: =IF(AND(F48<=7,LEN(C48)<=4096),"OK","ошибка")
A49: K3 | B49: ЕГЭ математика | C49: решать егэ математика профиль онлайн | D49: Тёплая | E49: 1 | F49: =LEN(TRIM(C49))-LEN(SUBSTITUTE(TRIM(C49)," ",""))+1 | G49: =IF(AND(F49<=7,LEN(C49)<=4096),"OK","ошибка")
A50: K3 | B50: ЕГЭ математика | C50: репетитор по математике профиль егэ онлайн | D50: Тёплая | E50: 1 | F50: =LEN(TRIM(C50))-LEN(SUBSTITUTE(TRIM(C50)," ",""))+1 | G50: =IF(AND(F50<=7,LEN(C50)<=4096),"OK","ошибка")
A51: K3 | B51: ЕГЭ математика | C51: ии репетитор математика профиль егэ | D51: Тёплая | E51: 1 | F51: =LEN(TRIM(C51))-LEN(SUBSTITUTE(TRIM(C51)," ",""))+1 | G51: =IF(AND(F51<=7,LEN(C51)<=4096),"OK","ошибка")
A52: K3 | B52: ЕГЭ математика | C52: разбор заданий егэ математика профиль | D52: Тёплая | E52: 1 | F52: =LEN(TRIM(C52))-LEN(SUBSTITUTE(TRIM(C52)," ",""))+1 | G52: =IF(AND(F52<=7,LEN(C52)<=4096),"OK","ошибка")
A53: K3 | B53: ЕГЭ математика | C53: варианты егэ математика профиль онлайн | D53: Тёплая | E53: 1 | F53: =LEN(TRIM(C53))-LEN(SUBSTITUTE(TRIM(C53)," ",""))+1 | G53: =IF(AND(F53<=7,LEN(C53)<=4096),"OK","ошибка")
A54: K3 | B54: ЕГЭ математика | C54: банк заданий фипи математика профиль | D54: Тёплая | E54: 1 | F54: =LEN(TRIM(C54))-LEN(SUBSTITUTE(TRIM(C54)," ",""))+1 | G54: =IF(AND(F54<=7,LEN(C54)<=4096),"OK","ошибка")
A55: K3 | B55: ЕГЭ математика | C55: пробный егэ математика профиль онлайн | D55: Тёплая | E55: 1 | F55: =LEN(TRIM(C55))-LEN(SUBSTITUTE(TRIM(C55)," ",""))+1 | G55: =IF(AND(F55<=7,LEN(C55)<=4096),"OK","ошибка")
A56: K3 | B56: ЕГЭ математика | C56: егэ математика профиль с нуля | D56: Тёплая | E56: 1 | F56: =LEN(TRIM(C56))-LEN(SUBSTITUTE(TRIM(C56)," ",""))+1 | G56: =IF(AND(F56<=7,LEN(C56)<=4096),"OK","ошибка")
... A164: K3 | B164: ЕГЭ география | C164: егэ география с нуля | D164: Тёплая | E164: 2 | F164: =LEN(TRIM(C164))-LEN(SUBSTITUTE(TRIM(C164)," ",""))+1 | G164: =IF(AND(F164<=7,LEN(C164)<=4096),"OK","ошибка")
A165: K4 | B165: Обществознание: эссе и развёрнутые ответы | C165: проверка эссе егэ обществознание | D165: Тёплая | E165: 2 | F165: =LEN(TRIM(C165))-LEN(SUBSTITUTE(TRIM(C165)," ",""))+1 | G165: =IF(AND(F165<=7,LEN(C165)<=4096),"OK","ошибка") | H165: У обществознания на платформе 1 847 заданий с критериями.
A166: K4 | B166: Обществознание: эссе и развёрнутые ответы | C166: проверка эссе по обществознанию онлайн | D166: Тёплая | E166: 2 | F166: =LEN(TRIM(C166))-LEN(SUBSTITUTE(TRIM(C166)," ",""))+1 | G166: =IF(AND(F166<=7,LEN(C166)<=4096),"OK","ошибка") | H166: У обществознания на платформе 1 847 заданий с критериями.
A167: K4 | B167: Обществознание: эссе и развёрнутые ответы | C167: проверить эссе егэ обществознание | D167: Тёплая | E167: 2 | F167: =LEN(TRIM(C167))-LEN(SUBSTITUTE(TRIM(C167)," ",""))+1 | G167: =IF(AND(F167<=7,LEN(C167)<=4096),"OK","ошибка") | H167: У обществознания на платформе 1 847 заданий с критериями.
A168: K4 | B168: Обществознание: эссе и развёрнутые ответы | C168: эссе егэ обществознание по критериям | D168: Тёплая | E168: 2 | F168: =LEN(TRIM(C168))-LEN(SUBSTITUTE(TRIM(C168)," ",""))+1 | G168: =IF(AND(F168<=7,LEN(C168)<=4096),"OK","ошибка") | H168: У обществознания на платформе 1 847 заданий с критериями.
...

Sheet Объявления
A1: Объявления для поиска
A2: Лимиты (справка Директа): заголовок 1 — 35 симв. без знаков препинания, заголовок 2 — 30, текст — 81; знаков препинания не больше 15; отображаемая ссылка — 20. Слова длиннее 22/23 символов проверены отдельно.
A4: Кампания | B4: Группа | C4: Вар. | D4: Заголовок 1 | E4: Заголовок 2 | F4: Текст | G4: Отображаемая ссылка | H4: URL (с метками) | I4: З1 симв. | J4: З1 знаки | K4: З2 симв. | L4: З2 знаки | M4: Текст симв. | N4: Текст знаки | O4: Проверка
A5: K2 | B5: ИИ-репетитор | C5: A | D5: ИИ-репетитор для ЕГЭ | E5: Объясняет, а не решает | F5: Разбор заданий по шагам и подсказки трёх уровней. Начните бесплатно | G5: ИИ-репетитор | H5: https://ege-tutor.ru/?utm_source=yandex&utm_medium=cpc&utm_campaign=k2_hot&utm_content={ad_id}&utm_term={keyword} | I5: =LEN(D5)-J5 | J5: =SUMPRODUCT(LEN(D5)-LEN(SUBSTITUTE(D5,{".",",","!","?",":",";","—","–","«","»","""","'","(",")"},""))) | K5: =LEN(E5)-L5 | L5: =SUMPRODUCT(LEN(E5)-LEN(SUBSTITUTE(E5,{".",",","!","?",":",";","—","–","«","»","""","'","(",")"},""))) | M5: =LEN(F5)-N5 | N5: =SUMPRODUCT(LEN(F5)-LEN(SUBSTITUTE(F5,{".",",","!","?",":",";","—","–","«","»","""","'","(",")"},""))) | O5: =IF(AND(I5<=35,J5<=15,K5<=30,L5<=15,M5<=81,N5<=15,LEN(G5)<=20),"OK","проверить")
A6: K2 | B6: ИИ-репетитор | C6: B | D6: Репетитор с ИИ для ЕГЭ | E6: Безлимит от 1990 ₽/мес | F6: Безлимитный ИИ-репетитор на 2 предмета от 1990 ₽ в месяц. Есть бесплатный старт | G6: ИИ-репетитор | H6: https://ege-tutor.ru/?utm_source=yandex&utm_medium=cpc&utm_campaign=k2_hot&utm_content={ad_id}&utm_term={keyword} | I6: =LEN(D6)-J6 | J6: =SUMPRODUCT(LEN(D6)-LEN(SUBSTITUTE(D6,{".",",","!","?",":",";","—","–","«","»","""","'","(",")"},""))) | K6: =LEN(E6)-L6 | L6: =SUMPRODUCT(LEN(E6)-LEN(SUBSTITUTE(E6,{".",",","!","?",":",";","—","–","«","»","""","'","(",")"},""))) | M6: =LEN(F6)-N6 | N6: =SUMPRODUCT(LEN(F6)-LEN(SUBSTITUTE(F6,{".",",","!","?",":",";","—","–","«","»","""","'","(",")"},""))) | O6: =IF(AND(I6<=35,J6<=15,K6<=30,L6<=15,M6<=81,N6<=15,LEN(G6)<=20),"OK","проверить")
A7: K2 | B7: Тренажёр ЕГЭ | C7: A | D7: Тренажёр ЕГЭ онлайн с ИИ | E7: Задания формата ФИПИ | F7: Решайте задания, получайте подсказки и разбор по шагам. Начните бесплатно | G7: Тренажёр-ЕГЭ | H7: https://ege-tutor.ru/?utm_source=yandex&utm_medium=cpc&utm_campaign=k2_hot&utm_content={ad_id}&utm_term={keyword} | I7: =LEN(D7)-J7 | J7: =SUMPRODUCT(LEN(D7)-LEN(SUBSTITUTE(D7,{".",",","!","?",":",";","—","–","«","»","""","'","(",")"},""))) | K7: =LEN(E7)-L7 | L7: =SUMPRODUCT(LEN(E7)-LEN(SUBSTITUTE(E7,{".",",","!","?",":",";","—","–","«","»","""","'","(",")"},""))) | M7: =LEN(F7)-N7 | N7: =SUMPRODUCT(LEN(F7)-LEN(SUBSTITUTE(F7,{".",",","!","?",":",";","—","–","«","»","""","'","(",")"},""))) | O7: =IF(AND(I7<=35,J7<=15,K7<=30,L7<=15,M7<=81,N7<=15,LEN(G7)<=20),"OK","проверить")
A8: K2 | B8: Тренажёр ЕГЭ | C8: B | D8: Пробные варианты ЕГЭ онлайн | E8: Экзамен-режим с таймером | F8: Тренируйтесь с таймером, разбирайте ошибки, следите за прогрессом по предметам | G8: Тренажёр-ЕГЭ | H8: https://ege-tutor.ru/?utm_source=yandex&utm_medium=cpc&utm_campaign=k2_hot&utm_content={ad_id}&utm_term={keyword} | I8: =LEN(D8)-J8 | J8: =SUMPRODUCT(LEN(D8)-LEN(SUBSTITUTE(D8,{".",",","!","?",":",";","—","–","«","»","""","'","(",")"},""))) | K8: =LEN(E8)-L8 | L8: =SUMPRODUCT(LEN(E8)-LEN(SUBSTITUTE(E8,{".",",","!","?",":",";","—","–","«","»","""","'","(",")"},""))) | M8: =LEN(F8)-N8 | N8: =SUMPRODUCT(LEN(F8)-LEN(SUBSTITUTE(F8,{".",",","!","?",":",";","—","–","«","»","""","'","(",")"},""))) | O8: =IF(AND(I8<=35,J8<=15,K8<=30,L8<=15,M8<=81,N8<=15,LEN(G8)<=20),"OK","проверить")
A9: K2 | B9: Платформа подготовки | C9: A | D9: Подготовка к ЕГЭ онлайн | E9: ИИ-репетитор и банк заданий | F9: Задания формата ФИПИ, персональный план и статистика. Первые шаги бесплатно | G9: Подготовка-ЕГЭ | H9: https://ege-tutor.ru/?utm_source=yandex&utm_medium=cpc&utm_campaign=k2_hot&utm_content={ad_id}&utm_term={keyword} | I9: =LEN(D9)-J9 | J9: =SUMPRODUCT(LEN(D9)-LEN(SUBSTITUTE(D9,{".",",","!","?",":",";","—","–","«","»","""","'","(",")"},""))) | K9: =LEN(E9)-L9 | L9: =SUMPRODUCT(LEN(E9)-LEN(SUBSTITUTE(E9,{".",",","!","?",":",";","—","–","«","»","""","'","(",")"},""))) | M9: =LEN(F9)-N9 | N9: =SUMPRODUCT(LEN(F9)-LEN(SUBSTITUTE(F9,{".",",","!","?",":",";","—","–","«","»","""","'","(",")"},""))) | O9: =IF(AND(I9<=35,J9<=15,K9<=30,L9<=15,M9<=81,N9<=15,LEN(G9)<=20),"OK","проверить")
A10: K2 | B10: Платформа подготовки | C10: B | D10: Платформа подготовки к ЕГЭ | E10: Начните бесплатно | F10: 3 обращения к ИИ-репетитору в день бесплатно. Безлимит — от 1990 ₽ в месяц | G10: Подготовка-ЕГЭ | H10: https://ege-tutor.ru/?utm_source=yandex&utm_medium=cpc&utm_campaign=k2_hot&utm_content={ad_id}&utm_term={keyword} | I10: =LEN(D10)-J10 | J10: =SUMPRODUCT(LEN(D10)-LEN(SUBSTITUTE(D10,{".",",","!","?",":",";","—","–","«","»","""","'","(",")"},""))) | K10: =LEN(E10)-L10 | L10: =SUMPRODUCT(LEN(E10)-LEN(SUBSTITUTE(E10,{".",",","!","?",":",";","—","–","«","»","""","'","(",")"},""))) | M10: =LEN(F10)-N10 | N10: =SUMPRODUCT(LEN(F10)-LEN(SUBSTITUTE(F10,{".",",","!","?",":",";","—","–","«","»","""","'","(",")"},""))) | O10: =IF(AND(I10<=35,J10<=15,K10<=30,L10<=15,M10<=81,N10<=15,LEN(G10)<=20),"OK","проверить")
A11: K2 | B11: ЕГЭ 2027 | C11: A | D11: Подготовка к ЕГЭ 2027 с ИИ | E11: Объясняет, а не решает | F11: Задания формата ФИПИ, подсказки и разбор по шагам. Есть бесплатный старт | G11: ЕГЭ-2027 | H11: https://ege-tutor.ru/?utm_source=yandex&utm_medium=cpc&utm_campaign=k2_hot&utm_content={ad_id}&utm_term={keyword} | I11: =LEN(D11)-J11 | J11: =SUMPRODUCT(LEN(D11)-LEN(SUBSTITUTE(D11,{".",",","!","?",":",";","—","–","«","»","""","'","(",")"},""))) | K11: =LEN(E11)-L11 | L11: =SUMPRODUCT(LEN(E11)-LEN(SUBSTITUTE(E11,{".",",","!","?",":",";","—","–","«","»","""","'","(",")"},""))) | M11: =LEN(F11)-N11 | N11: =SUMPRODUCT(LEN(F11)-LEN(SUBSTITUTE(F11,{".",",","!","?",":",";","—","–","«","»","""","'","(",")"},""))) | O11: =IF(AND(I11<=35,J11<=15,K11<=30,L11<=15,M11<=81,N11<=15,LEN(G11)<=20),"OK","проверить")
A12: K2 | B12: ЕГЭ 2027 | C12: B | D12: ЕГЭ 2027: тренажёр с ИИ | E12: Безлимит от 1990 ₽/мес | F12: ИИ-репетитор по вашим предметам: подсказки, разбор заданий, план подготовки | G12: ЕГЭ-2027 | H12: https://ege-tutor.ru/?utm_source=yandex&utm_medium=cpc&utm_campaign=k2_hot&utm_content={ad_id}&utm_term={keyword} | I12: =LEN(D12)-J12 | J12: =SUMPRODUCT(LEN(D12)-LEN(SUBSTITUTE(D12,{".",",","!","?",":",";","—","–","«","»","""","'","(",")"},""))) | K12: =LEN(E12)-L12 | L12: =SUMPRODUCT(LEN(E12)-LEN(SUBSTITUTE(E12,{".",",","!","?",":",";","—","–","«","»","""","'","(",")"},""))) | M12: =LEN(F12)-N12 | N12: =SUMPRODUCT(LEN(F12)-LEN(SUBSTITUTE(F12,{".",",","!","?",":",";","—","–","«","»","""","'","(",")"},""))) | O12: =IF(AND(I12<=35,J12<=15,K12<=30,L12<=15,M12<=81,N12<=15,LEN(G12)<=20),"OK","проверить")
A13: K3 | B13: ЕГЭ математика | C13: A | D13: ЕГЭ математика: тренажёр с ИИ | E13: Объясняет, а не решает | F13: Задания по математике профиль: разбор по шагам и подсказки. Начните бесплатно | G13: Математика-ЕГЭ | H13: https://ege-tutor.ru/?utm_source=yandex&utm_medium=cpc&utm_campaign=k3_math&utm_content={ad_id}&utm_term={keyword} | I13: =LEN(D13)-J13 | J13: =SUMPRODUCT(LEN(D13)-LEN(SUBSTITUTE(D13,{".",",","!","?",":",";","—","–","«","»","""","'","(",")"},""))) | K13: =LEN(E13)-L13 | L13: =SUMPRODUCT(LEN(E13)-LEN(SUBSTITUTE(E13,{".",",","!","?",":",";","—","–","«","»","""","'","(",")"},""))) | M13: =LEN(F13)-N13 | N13: =SUMPRODUCT(LEN(F13)-LEN(SUBSTITUTE(F13,{".",",","!","?",":",";","—","–","«","»","""","'","(",")"},""))) | O13: =IF(AND(I13<=35,J13<=15,K13<=30,L13<=15,M13<=81,N13<=15,LEN(G13)<=20),"OK","проверить")
A14: K3 | B14: ЕГЭ математика | C14: B | D14: ИИ-репетитор: математика ЕГЭ | E14: От 1990 ₽/мес, безлимит | F14: Безлимитный ИИ-репетитор на 2 предмета от 1990 ₽ в месяц. Бесплатный старт есть | G14: Математика-ЕГЭ | H14: https://ege-tutor.ru/?utm_source=yandex&utm_medium=cpc&utm_campaign=k3_math&utm_content={ad_id}&utm_term={keyword} | I14: =LEN(D14)-J14 | J14: =SUMPRODUCT(LEN(D14)-LEN(SUBSTITUTE(D14,{".",",","!","?",":",";","—","–","«","»","""","'","(",")"},""))) | K14: =LEN(E14)-L14 | L14: =SUMPRODUCT(LEN(E14)-LEN(SUBSTITUTE(E14,{".",",","!","?",":",";","—","–","«","»","""","'","(",")"},""))) | M14: =LEN(F14)-N14 | N14: =SUMPRODUCT(LEN(F14)-LEN(SUBSTITUTE(F14,{".",",","!","?",":",";","—","–","«","»","""","'","(",")"},""))) | O14: =IF(AND(I14<=35,J14<=15,K14<=30,L14<=15,M14<=81,N14<=15,LEN(G14)<=20),"OK","проверить")
A15: K3 | B15: ЕГЭ русский язык | C15: A | D15: ЕГЭ русский язык: тренажёр с ИИ | E15: Объясняет, а не решает | F15: Задания по русскому языку: разбор по шагам и подсказки. Начните бесплатно | G15: Русский-язык-ЕГЭ | H15: https://ege-tutor.ru/?utm_source=yandex&utm_medium=cpc&utm_campaign=k3_rus&utm_content={ad_id}&utm_term={keyword} | I15: =LEN(D15)-J15 | J15: =SUMPRODUCT(LEN(D15)-LEN(SUBSTITUTE(D15,{".",",","!","?",":",";","—","–","«","»","""","'","(",")"},""))) | K15: =LEN(E15)-L15 | L15: =SUMPRODUCT(LEN(E15)-LEN(SUBSTITUTE(E15,{".",",","!","?",":",";","—","–","«","»","""","'","(",")"},""))) | M15: =LEN(F15)-N15 | N15: =SUMPRODUCT(LEN(F15)-LEN(SUBSTITUTE(F15,{".",",","!","?",":",";","—","–","«","»","""","'","(",")"},""))) | O15: =IF(AND(I15<=35,J15<=15,K15<=30,L15<=15,M15<=81,N15<=15,LEN(G15)<=20),"OK","проверить")
A16: K3 | B16: ЕГЭ русский язык | C16: B | D16: ИИ-репетитор: русский язык ЕГЭ | E16: От 1990 ₽/мес, безлимит | F16: Безлимитный ИИ-репетитор на 2 предмета от 1990 ₽ в месяц. Бесплатный старт есть | G16: Русский-язык-ЕГЭ | H16: https://ege-tutor.ru/?utm_source=yandex&utm_medium=cpc&utm_campaign=k3_rus&utm_content={ad_id}&utm_term={keyword} | I16: =LEN(D16)-J16 | J16: =SUMPRODUCT(LEN(D16)-LEN(SUBSTITUTE(D16,{".",",","!","?",":",";","—","–","«","»","""","'","(",")"},""))) | K16: =LEN(E16)-L16 | L16: =SUMPRODUCT(LEN(E16)-LEN(SUBSTITUTE(E16,{".",",","!","?",":",";","—","–","«","»","""","'","(",")"},""))) | M16: =LEN(F16)-N16 | N16: =SUMPRODUCT(LEN(F16)-LEN(SUBSTITUTE(F16,{".",",","!","?",":",";","—","–","«","»","""","'","(",")"},""))) | O16: =IF(AND(I16<=35,J16<=15,K16<=30,L16<=15,M16<=81,N16<=15,LEN(G16)<=20),"OK","проверить")
... A54: K7 | B54: Начал оплату, не завершил | C54: A | D54: Завершите подключение тарифа | E54: ИИ-репетитор без лимита | F54: Оплата занимает пару минут. Тариф включается сразу после подтверждения платежа | G54: Тарифы | H54: https://ege-tutor.ru/tariffs?utm_source=yandex&utm_medium=cpc&utm_campaign=k7_checkout&utm_content={ad_id}&utm_term={keyword} | I54: =LEN(D54)-J54 | J54: =SUMPRODUCT(LEN(D54)-LEN(SUBSTITUTE(D54,{".",",","!","?",":",";","—","–","«","»","""","'","(",")"},""))) | K54: =LEN(E54)-L54 | L54: =SUMPRODUCT(LEN(E54)-LEN(SUBSTITUTE(E54,{".",",","!","?",":",";","—","–","«","»","""","'","(",")"},""))) | M54: =LEN(F54)-N54 | N54: =SUMPRODUCT(LEN(F54)-LEN(SUBSTITUTE(F54,{".",",","!","?",":",";","—","–","«","»","""","'","(",")"},""))) | O54: =IF(AND(I54<=35,J54<=15,K54<=30,L54<=15,M54<=81,N54<=15,LEN(G54)<=20),"OK","проверить")

Sheet Минус-слова
A1: Минус-слова
A2: «Все кампании» — на уровне кампаний (добавить в каждую). Остальные — только в указанную кампанию.
A4: Область | B4: Минус-слово / фраза | C4: Зачем | E4: Знаков без пробелов (лимит: кампания 20 000) | F4: Значение
A5: Все кампании | B5: гдз | C5: Ищут готовые ответы, а не тренажёр (и противоречит идее «ИИ объясняет, а не решает»). | E5: Все кампании | F5: =SUMPRODUCT((A$5:A$146="Все кампании")*LEN(SUBSTITUTE(B$5:B$146," ","")))
A6: Все кампании | B6: решебник | C6: Ищут готовые ответы, а не тренажёр (и противоречит идее «ИИ объясняет, а не решает»). | E6: K2 | F6: =SUMPRODUCT((A$5:A$146="K2")*LEN(SUBSTITUTE(B$5:B$146," ","")))
A7: Все кампании | B7: готовые ответы | C7: Ищут готовые ответы, а не тренажёр (и противоречит идее «ИИ объясняет, а не решает»). | E7: K3 | F7: =SUMPRODUCT((A$5:A$146="K3")*LEN(SUBSTITUTE(B$5:B$146," ","")))
A8: Все кампании | B8: ответы | C8: Ищут готовые ответы, а не тренажёр (и противоречит идее «ИИ объясняет, а не решает»). | E8: K4 | F8: =SUMPRODUCT((A$5:A$146="K4")*LEN(SUBSTITUTE(B$5:B$146," ","")))
A9: Все кампании | B9: ответы на егэ | C9: Ищут готовые ответы, а не тренажёр (и противоречит идее «ИИ объясняет, а не решает»). | E9: K5 | F9: =SUMPRODUCT((A$5:A$146="K5")*LEN(SUBSTITUTE(B$5:B$146," ","")))
A10: Все кампании | B10: списать | C10: Ищут готовые ответы, а не тренажёр (и противоречит идее «ИИ объясняет, а не решает»). | E10: K6 | F10: =SUMPRODUCT((A$5:A$146="K6")*LEN(SUBSTITUTE(B$5:B$146," ","")))
A11: Все кампании | B11: шпаргалка | C11: Ищут готовые ответы, а не тренажёр (и противоречит идее «ИИ объясняет, а не решает»).
A12: Все кампании | B12: шпаргалки | C12: Ищут готовые ответы, а не тренажёр (и противоречит идее «ИИ объясняет, а не решает»). | E12: Лимит Директа на кампанию (справка) | F12: 20000
A13: Все кампании | B13: скачать | C13: Нелегальный контент и утечки материалов экзамена.
A14: Все кампании | B14: торрент | C14: Нелегальный контент и утечки материалов экзамена.
A15: Все кампании | B15: pdf | C15: Нелегальный контент и утечки материалов экзамена.
A16: Все кампании | B16: слив | C16: Нелегальный контент и утечки материалов экзамена.
A17: Все кампании | B17: слитые | C17: Нелегальный контент и утечки материалов экзамена.
A18: Все кампании | B18: утечка | C18: Нелегальный контент и утечки материалов экзамена.
A19: Все кампании | B19: утечки | C19: Нелегальный контент и утечки материалов экзамена.
A20: Все кампании | B20: огэ | C20: Платформа только для ЕГЭ.
A21: Все кампании | B21: впр | C21: Платформа только для ЕГЭ.
A22: Все кампании | B22: гвэ | C22: Платформа только для ЕГЭ.
A23: Все кампании | B23: 5 класс | C23: Не наша аудитория (до 10 класса).
A24: Все кампании | B24: 6 класс | C24: Не наша аудитория (до 10 класса).
... A146: K6 | B146: географии | C146: Предметные запросы обслуживает K3.

Sheet Быстрые ссылки
A1: Быстрые ссылки
A2: Заголовок — до 30 символов, описание — до 60. Ссылки ведут на «/» и «/tariffs» (других адресов у приложения нет), различаются метками.
A4: № | B4: Заголовок | C4: Описание | D4: URL | E4: Зн. заг. | F4: Зн. опис. | G4: Проверка
A5: 1 | B5: Тарифы и цены | C5: От 1990 ₽ в месяц. Есть бесплатный тариф | D5: https://ege-tutor.ru/tariffs?utm_source=yandex&utm_medium=cpc&utm_campaign=sitelinks&utm_content=sl_tariffs | E5: =LEN(B5) | F5: =LEN(C5) | G5: =IF(AND(E5<=30,F5<=60),"OK","проверить")
A6: 2 | B6: Попробовать бесплатно | C6: 3 обращения к ИИ-репетитору в день | D6: https://ege-tutor.ru/?utm_source=yandex&utm_medium=cpc&utm_campaign=sitelinks&utm_content=sl_free | E6: =LEN(B6) | F6: =LEN(C6) | G6: =IF(AND(E6<=30,F6<=60),"OK","проверить")
A7: 3 | B7: Как работает ИИ | C7: Подсказки трёх уровней и разбор по шагам | D7: https://ege-tutor.ru/?utm_source=yandex&utm_medium=cpc&utm_campaign=sitelinks&utm_content=sl_ai | E7: =LEN(B7) | F7: =LEN(C7) | G7: =IF(AND(E7<=30,F7<=60),"OK","проверить")
A8: 4 | B8: Банк заданий | C8: Задания формата ФИПИ по 11 предметам | D8: https://ege-tutor.ru/?utm_source=yandex&utm_medium=cpc&utm_campaign=sitelinks&utm_content=sl_bank | E8: =LEN(B8) | F8: =LEN(C8) | G8: =IF(AND(E8<=30,F8<=60),"OK","проверить")
A9: 5 | B9: Экзамен-режим | C9: Тренировка с таймером и разбором ошибок | D9: https://ege-tutor.ru/?utm_source=yandex&utm_medium=cpc&utm_campaign=sitelinks&utm_content=sl_exam | E9: =LEN(B9) | F9: =LEN(C9) | G9: =IF(AND(E9<=30,F9<=60),"OK","проверить")

Sheet Уточнения
A1: Уточнения
A2: До 25 символов с пробелами каждое.
A4: № | B4: Текст | C4: Симв. | D4: Проверка
A5: 1 | B5: Задания формата ФИПИ | C5: =LEN(B5) | D5: =IF(C5<=25,"OK","проверить")
A6: 2 | B6: ИИ объясняет, не решает | C6: =LEN(B6) | D6: =IF(C6<=25,"OK","проверить")
A7: 3 | B7: 3 уровня подсказок | C7: =LEN(B7) | D7: =IF(C7<=25,"OK","проверить")
A8: 4 | B8: Экзамен-режим с таймером | C8: =LEN(B8) | D8: =IF(C8<=25,"OK","проверить")
A9: 5 | B9: Проверка по критериям | C9: =LEN(B9) | D9: =IF(C9<=25,"OK","проверить")
A10: 6 | B10: Бесплатный старт | C10: =LEN(B10) | D10: =IF(C10<=25,"OK","проверить")
A11: 7 | B11: Персональный план | C11: =LEN(B11) | D11: =IF(C11<=25,"OK","проверить")
A12: 8 | B12: Тарифы от 1990 ₽/мес | C12: =LEN(B12) | D12: =IF(C12<=25,"OK","проверить")
A13: 9 | B13: 11 предметов ЕГЭ | C13: =LEN(B13) | D13: =IF(C13<=25,"OK","проверить")

Sheet Мастер кампаний
A1: Мастер кампаний (K1)
A2: Заголовок — до 56 знаков, дополнительный заголовок — до 30, текст — до 81. Яндекс сам комбинирует и подбирает аудиторию.
A4: № | B4: Заголовок | C4: Симв. | D4: Проверка
A5: 1 | B5: ИИ-репетитор для ЕГЭ: объясняет, а не решает | C5: =LEN(B5) | D5: =IF(C5<=56,"OK","проверить")
A6: 2 | B6: Подготовка к ЕГЭ онлайн с ИИ-репетитором | C6: =LEN(B6) | D6: =IF(C6<=56,"OK","проверить")
A7: 3 | B7: Тренажёр ЕГЭ: задания формата ФИПИ и подсказки | C7: =LEN(B7) | D7: =IF(C7<=56,"OK","проверить")
A8: 4 | B8: Готовьтесь к ЕГЭ 2027 с ИИ-репетитором | C8: =LEN(B8) | D8: =IF(C8<=56,"OK","проверить")
A9: 5 | B9: 11 предметов ЕГЭ: задания и ИИ-репетитор | C9: =LEN(B9) | D9: =IF(C9<=56,"OK","проверить")
A11: № | B11: Дополнительный заголовок | C11: Без знаков | D11: Проверка
A12: 1 | B12: Начните бесплатно | C12: =LEN(B12)-SUMPRODUCT(LEN(B12)-LEN(SUBSTITUTE(B12,{".",",","!","?",":",";","—","–","«","»","""","'","(",")"},""))) | D12: =IF(C12<=30,"OK","проверить")
A13: 2 | B13: Безлимит от 1990 ₽/мес | C13: =LEN(B13)-SUMPRODUCT(LEN(B13)-LEN(SUBSTITUTE(B13,{".",",","!","?",":",";","—","–","«","»","""","'","(",")"},""))) | D13: =IF(C13<=30,"OK","проверить")
A14: 3 | B14: Подсказки трёх уровней | C14: =LEN(B14)-SUMPRODUCT(LEN(B14)-LEN(SUBSTITUTE(B14,{".",",","!","?",":",";","—","–","«","»","""","'","(",")"},""))) | D14: =IF(C14<=30,"OK","проверить")
A15: 4 | B15: Разбор заданий по шагам | C15: =LEN(B15)-SUMPRODUCT(LEN(B15)-LEN(SUBSTITUTE(B15,{".",",","!","?",":",";","—","–","«","»","""","'","(",")"},""))) | D15: =IF(C15<=30,"OK","проверить")
A16: 5 | B16: Экзамен-режим с таймером | C16: =LEN(B16)-SUMPRODUCT(LEN(B16)-LEN(SUBSTITUTE(B16,{".",",","!","?",":",";","—","–","«","»","""","'","(",")"},""))) | D16: =IF(C16<=30,"OK","проверить")
A18: № | B18: Текст | C18: Без знаков | D18: Проверка
A19: 1 | B19: Разбор заданий по шагам и подсказки трёх уровней. Начните бесплатно | C19: =LEN(B19)-SUMPRODUCT(LEN(B19)-LEN(SUBSTITUTE(B19,{".",",","!","?",":",";","—","–","«","»","""","'","(",")"},""))) | D19: =IF(C19<=81,"OK","проверить")
A20: 2 | B20: Тренируйтесь с таймером, разбирайте ошибки, следите за прогрессом по предметам | C20: =LEN(B20)-SUMPRODUCT(LEN(B20)-LEN(SUBSTITUTE(B20,{".",",","!","?",":",";","—","–","«","»","""","'","(",")"},""))) | D20: =IF(C20<=81,"OK","проверить")
A21: 3 | B21: Безлимитный ИИ-репетитор на 2 предмета от 1990 ₽ в месяц. Бесплатный старт есть | C21: =LEN(B21)-SUMPRODUCT(LEN(B21)-LEN(SUBSTITUTE(B21,{".",",","!","?",":",";","—","–","«","»","""","'","(",")"},""))) | D21: =IF(C21<=81,"OK","проверить")
A22: 4 | B22: Ребёнок учится сам: ИИ подсказывает и объясняет, но не решает за него | C22: =LEN(B22)-SUMPRODUCT(LEN(B22)-LEN(SUBSTITUTE(B22,{".",",","!","?",":",";","—","–","«","»","""","'","(",")"},""))) | D22: =IF(C22<=81,"OK","проверить")
B24: Название компании: ЕГЭ·ПРО. Кнопка: «Попробовать» (если есть такой вариант). Ссылка: https://ege-tutor.ru/ с метками (utm_campaign=k1_master).
A26: № | B26: Изображения, которые нужно подготовить (скриншоты платформы) | E26: Формат
A27: 1 | B27: Экран задания с подсказкой ИИ-репетитора (боковой чат) | E27: квадрат 1:1 и горизонтальный 16:9
A28: 2 | B28: Разбор решения по шагам с формулами | E28: квадрат 1:1 и горизонтальный 16:9
A29: 3 | B29: Экзамен-режим с таймером | E29: горизонтальный 16:9
A30: 4 | B30: Статистика и персональный план | E30: квадрат 1:1
A31: 5 | B31: Страница тарифов (цены и бесплатный старт) | E31: горизонтальный 16:9
B32: Точные требования к размерам показывает сам Мастер при загрузке — сверю при заполнении. Скриншоты без персональных данных и без реальных имён/почт.
A34: № | B34: Образец ключевых фраз для Мастера (необязательно)
A35: 1 | B35: ии репетитор егэ
A36: 2 | B36: тренажер егэ онлайн
A37: 3 | B37: подготовка к егэ онлайн
A38: 4 | B38: нейросеть для подготовки к егэ
A39: 5 | B39: платформа для подготовки к егэ
A40: 6 | B40: подготовка к егэ 2027
A41: 7 | B41: ии репетитор для подготовки к егэ
A42: 8 | B42: решать задания егэ онлайн

Sheet Ретаргетинг и LAL
A1: Ретаргетинг и Look-alike (волна 2)
A2: Сегменты создаются в Метрике/Аудиториях. Тексты объявлений — на листе «Объявления» (K7).
A4: Сегмент | B4: Условие в Метрике | C4: Окно | D4: Что показываем | E4: Посадочная
A5: Был на сайте, не зарегистрировался | B5: Визит на сайт И НЕ цель signup | C5: 14 дней | D5: Бесплатный старт + УТП «объясняет, а не решает» | E5: /
A6: Зарегистрировался, не оплатил | B6: Цель signup И НЕ цель purchase | C6: 14 дней | D6: Безлимит и тарифы | E6: /tariffs
A7: Упёрся в дневной лимит | B7: Цель ai_limit_reached И НЕ purchase | C7: 7 дней | D7: Самый горячий сегмент: безлимит | E7: /tariffs
A8: Начал оплату, не завершил | B8: Цель checkout_start И НЕ purchase | C8: 7 дней | D8: Напоминание завершить подключение | E8: /tariffs
A9: Оплатил (ИСКЛЮЧИТЬ из показов) | B9: Цель purchase | C9: 180 дней | D9: Не показывать рекламу тарифа | E9: —
A10: Look-alike от оплативших | B10: Яндекс.Аудитории → «Похожие»: сегмент purchase | C10: — | D10: Расширение охвата | E10: /
A12: Look-alike имеет смысл, когда оплативших наберётся 100–200 (по инструкции). До этого сегмент слишком мал.

Sheet Цели и метки
A1: Цели Метрики и метки ссылок
A2: Счётчик 112809756. Цели создаются в Метрике (Настройка → Цели). Сайт отправляет JS-события сам.
A4: Название цели | B4: Тип | C4: Условие / идентификатор | D4: Зачем
A5: signup | B5: JavaScript-событие | C5: signup | D5: Регистрация — основная ранняя цель для обучения
A6: first_ai_use | B6: JavaScript-событие | C6: first_ai_use | D6: Первое обращение к ИИ (раз на браузер)
A7: checkout_start | B7: JavaScript-событие | C7: checkout_start | D7: Нажал «Выбрать» на платном тарифе
A8: purchase | B8: JavaScript-событие | C8: purchase | D8: Покупка (с суммой) — главная цель
A9: task_opened | B9: JavaScript-событие | C9: task_opened | D9: Открыл задание (раз за сессию)
A10: ai_limit_reached | B10: JavaScript-событие | C10: ai_limit_reached | D10: Упёрся в лимит (раз в день)
A11: exam_mode_start | B11: JavaScript-событие | C11: exam_mode_start | D11: Запустил экзамен-режим или пробник
A12: essay_check_used | B12: JavaScript-событие | C12: essay_check_used | D12: Проверка развёрнутого ответа
A13: tariffs_view | B13: URL содержит | C13: /tariffs | D13: Просмотр тарифов (замена checkout_start, пока нет данных)
A14: offer_view | B14: URL содержит | C14: /oferta | D14: Читает оферту — сигнал перед оплатой
A15: email_verified | B15: URL содержит | C15: /verify-email | D15: Подтверждение почты (только для контроля)
A16: payment_return | B16: URL содержит | C16: /payment/return | D16: Возврат из ЮKassa (успех ИЛИ отмена — не покупка)
A18: Метки в ссылках
A19: Шаблон | B19: utm_source=yandex&utm_medium=cpc&utm_campaign=<код кампании>&utm_content={ad_id}&utm_term={keyword}
A20: Примечание | B20: {ad_id} и {keyword} — макросы Директа. В кабинете также включить автоматическую разметку для Метрики (yclid). Названия макросов сверю с экраном при заполнении.

Sheet Чек-лист
A1: Чек-лист запуска
A2: Кто: «Вы» — то, что я делать не буду или не могу (вход, деньги, юридические данные, подтверждения). «Я» — заполнение кабинета.
A4: № | B4: Кто | C4: Что сделать | D4: Статус | E4: Примечание
A5: 1 | B5: Вы | C5: Войти в кабинет Директа (адрес с ulogin=ege-pro-ai): логин, пароль, SMS и капчи — только вы. Я работаю в уже открытой вами сессии. | D5: Не начато
A6: 2 | B6: Вы | C6: Принять оферту Директа и указать данные рекламодателя для маркировки рекламы (ИНН и др.). | D6: Не начато | E6: Юридические данные вношу только по вашему прямому разрешению на каждый шаг.
A7: 3 | B7: Вы | C7: Проверить актуальную акцию для новых рекламодателей, пополнить баланс (промокод вводится при первом пополнении). | D7: Не начато | E7: Пополнение и платежи — только вы.
A8: 4 | B8: Вы | C8: Создать в Метрике цели по листу «Цели и метки» (JS-события и URL-цели) и включить электронную коммерцию (уже включена). | D8: Не начато
A9: 5 | B9: Вы | C9: Проверить «Настройки» и «Кампании» этой книги: бюджеты, регион, доли. | D9: Не начато | E9: Без вашего утверждения бюджетов кабинет не заполняю.
A10: 6 | B10: Вы | C10: Прогнать фразы через «Прогноз бюджета» в Директе и убрать нулевые и слишком дорогие. | D10: Не начато | E10: Или разрешить мне сделать это в кабинете и показать результат.
A11: 7 | B11: Я | C11: Создать K2 «Поиск | ИИ-репетитор и тренажёр»: группы, фразы, минус-слова, объявления, быстрые ссылки, уточнения. | D11: Не начато | E11: До отправки на модерацию.
A12: 8 | B12: Я | C12: Создать K3 «Поиск | Предметы» — группы волны 1 (математика, русский, обществознание, физика). | D12: Не начато | E12: До отправки на модерацию.
A13: 9 | B13: Я | C13: Создать K1 «Мастер кампаний»: тексты, изображения (после того как вы их подготовите), счётчик 112809756. | D13: Не начато
A14: 10 | B14: Я | C14: Указать счётчик Метрики и цели в каждой кампании, включить разметку ссылок. | D14: Не начато
A15: 11 | B15: Вы | C15: Проверить кампании вместе со мной и дать прямое «да» на отправку на модерацию / включение показов. | D15: Не начато | E15: Это трата денег — без вашего «да» не запускаю.
A16: 12 | B16: Я | C16: Через 1–2 недели: K4, K5, K6 и ретаргетинг K7 (волна 2), группы предметов волны 2 в K3. | D16: Не начато | E16: Если данные покажут, что что-то не работает — сначала правим, потом расширяем.
A17: 13 | B17: Вы + я | C17: Раз в неделю: отчёт по площадкам и поисковым фразам, минус-слова, CPA по целям, перераспределение бюджета (раздел 10 инструкции). | D17: Не начато
